Workbook
Name NativeTimeline_Date: #N/A
Name Slicer_Category: #N/A
Name Slicer_Month: #N/A
Name Slicer_Payment_Method: #N/A

Sheet Dashboard

Sheet  Dataset
V1: CONDITIONAL FORMATTING | W1: TOTAL SALES | X1: GROUP BY | Z1: FILETR
A2: Transaction_ID | B2: Date | C2: Day | D2: Month | E2: Year | F2: Customer_ID | G2: Customer_Name | H2: Product_ID | I2: Product_Name | J2: Category | K2: Quantity | L2: Unit_Price | M2: Payment_Method | N2: Region | O2: Customer_Segment | P2: Customer_Since | Q2: Total_Amount | R2: TODAY | S2: NOW | T2: DATEDIF | U2: EOMONTH | V2: Total_Sales | W2: =SUM(Q2:Q251) -> 228922.5 | X2: {=_xlfn.UNIQUE(G2:G252)} -> Customer_Name | Y2: Total Sales Per Customer | Z2: {=_xlfn._xlws.FILTER(Dataset[],(Dataset[Category]="Electronics")*(Dataset[Region]="North"))} -> TRX0230 | AA2: 45409 | AB2: 27 | AC2: 04 | AD2: 2024 | AE2: CUST027 | AF2: George Adams | AG2: P001 | AH2: Laptop | AI2: Electronics | AJ2: 1 | AK2: 899.99 | AL2: Debit Card | AM2: North | AN2: Standard | AO2: 44920 | AP2: 899.99
A3: TRX0155 | B3: 45393 | C3: =TEXT(B3,"DD") -> 11 | D3: =TEXT(B3,"mm") -> 04 | E3: =TEXT(B3,"YYYY") -> 2024 | F3: CUST023 | G3: Paul Baker | H3: P009 | I3: Monitor | J3: Electronics | K3: 3 | L3: 249.99 | M3: Cash | N3: Central | O3: Basic | P3: 44425 | Q3: 749.97 | R3: =TODAY() -> 46063 | S3: =NOW() -> 46063.524 | T3: =' Dataset'!$B3-' Dataset'!$P3 -> 968 | U3: =EOMONTH(' Dataset'!$B3, 0) -> 45412 | V3: 749.97 | X3: Paul Baker | Y3: =SUMIFS(Dataset[Total_Amount], Dataset[Customer_Name], X3) -> 8309.74 | Z3: TRX0134 | AA3: 45410 | AB3: 28 | AC3: 04 | AD3: 2024 | AE3: CUST010 | AF3: Maria Garcia | AG3: P002 | AH3: Smartphone | AI3: Electronics | AJ3: 2 | AK3: 699.99 | AL3: Cash | AM3: North | AN3: Basic | AO3: 44781 | AP3: 1399.98
A4: TRX0023 | B4: 45396 | C4: =TEXT(B4,"DD") -> 14 | D4: =TEXT(B4,"mm") -> 04 | E4: =TEXT(B4,"YYYY") -> 2024 | F4: CUST013 | G4: Joseph Jackson | H4: P009 | I4: Monitor | J4: Electronics | K4: 3 | L4: 249.99 | M4: Credit Card | N4: Central | O4: Premium | P4: 44575 | Q4: 749.97 | T4: =' Dataset'!$B4-' Dataset'!$P4 -> 821 | U4: =EOMONTH(' Dataset'!$B4, 0) -> 45412 | V4: 749.97 | X4: Joseph Jackson | Y4: =SUMIFS(Dataset[Total_Amount], Dataset[Customer_Name], X4) -> 6949.84 | Z4: TRX0222 | AA4: 45410 | AB4: 28 | AC4: 04 | AD4: 2024 | AE4: CUST048 | AF4: Virginia Sanders | AG4: P009 | AH4: Monitor | AI4: Electronics | AJ4: 3 | AK4: 249.99 | AL4: Credit Card | AM4: North | AN4: Premium | AO4: 45224 | AP4: 749.97
A5: TRX0139 | B5: 45399 | C5: =TEXT(B5,"DD") -> 17 | D5: =TEXT(B5,"mm") -> 04 | E5: =TEXT(B5,"YYYY") -> 2024 | F5: CUST021 | G5: Kevin Scott | H5: P005 | I5: Blender | J5: Appliances | K5: 3 | L5: 59.99 | M5: PayPal | N5: South | O5: Standard | P5: 45262 | Q5: 179.97 | T5: =' Dataset'!$B5-' Dataset'!$P5 -> 137 | U5: =EOMONTH(' Dataset'!$B5, 0) -> 45412 | V5: 179.97 | X5: Kevin Scott | Y5: =SUMIFS(Dataset[Total_Amount], Dataset[Customer_Name], X5) -> 3259.87 | Z5: TRX0204 | AA5: 45415 | AB5: 03 | AC5: 05 | AD5: 2024 | AE5: CUST044 | AF5: Cynthia Price | AG5: P009 | AH5: Monitor | AI5: Electronics | AJ5: 4 | AK5: 249.99 | AL5: PayPal | AM5: North | AN5: Standard | AO5: 44468 | AP5: 999.96
A6: TRX0043 | B6: 45400 | C6: =TEXT(B6,"DD") -> 18 | D6: =TEXT(B6,"mm") -> 04 | E6: =TEXT(B6,"YYYY") -> 2024 | F6: CUST046 | G6: Kathleen Bennett | H6: P005 | I6: Blender | J6: Appliances | K6: 3 | L6: 59.99 | M6: Cash | N6: North | O6: Premium | P6: 45114 | Q6: 179.97 | T6: =' Dataset'!$B6-' Dataset'!$P6 -> 286 | U6: =EOMONTH(' Dataset'!$B6, 0) -> 45412 | V6: 179.97 | X6: Kathleen Bennett | Y6: =SUMIFS(Dataset[Total_Amount], Dataset[Customer_Name], X6) -> 4309.81 | Z6: TRX0004 | AA6: 45424 | AB6: 12 | AC6: 05 | AD6: 2024 | AE6: CUST012 | AF6: Patricia Moore | AG6: P010 | AH6: Keyboard | AI6: Electronics | AJ6: 5 | AK6: 89.99 | AL6: Cash | AM6: North | AN6: Premium | AO6: 44919 | AP6: 449.95
A7: TRX0212 | B7: 45400 | C7: =TEXT(B7,"DD") -> 18 | D7: =TEXT(B7,"mm") -> 04 | E7: =TEXT(B7,"YYYY") -> 2024 | F7: CUST003 | G7: Michael Brown | H7: P008 | I7: Bookshelf | J7: Furniture | K7: 5 | L7: 149.99 | M7: Credit Card | N7: North | O7: Premium | P7: 45295 | Q7: 749.95 | T7: =' Dataset'!$B7-' Dataset'!$P7 -> 105 | U7: =EOMONTH(' Dataset'!$B7, 0) -> 45412 | V7: 749.95 | X7: Michael Brown | Y7: =SUMIFS(Dataset[Total_Amount], Dataset[Customer_Name], X7) -> 6169.74 | Z7: TRX0117 | AA7: 45444 | AB7: 01 | AC7: 06 | AD7: 2024 | AE7: CUST017 | AF7: Charles Allen | AG7: P010 | AH7: Keyboard | AI7: Electronics | AJ7: 1 | AK7: 89.99 | AL7: Cash | AM7: North | AN7: Basic | AO7: 45141 | AP7: 89.99
A8: TRX0092 | B8: 45403 | C8: =TEXT(B8,"DD") -> 21 | D8: =TEXT(B8,"mm") -> 04 | E8: =TEXT(B8,"YYYY") -> 2024 | F8: CUST024 | G8: Dorothy Nelson | H8: P005 | I8: Blender | J8: Appliances | K8: 2 | L8: 59.99 | M8: Cash | N8: West | O8: Standard | P8: 44746 | Q8: 119.98 | T8: =' Dataset'!$B8-' Dataset'!$P8 -> 657 | U8: =EOMONTH(' Dataset'!$B8, 0) -> 45412 | V8: 119.98 | X8: Dorothy Nelson | Y8: =SUMIFS(Dataset[Total_Amount], Dataset[Customer_Name], X8) -> 8269.79 | Z8: TRX0114 | AA8: 45481 | AB8: 08 | AC8: 07 | AD8: 2024 | AE8: CUST018 | AF8: Barbara Young | AG8: P010 | AH8: Keyboard | AI8: Electronics | AJ8: 5 | AK8: 89.99 | AL8: Debit Card | AM8: North | AN8: Premium | AO8: 45161 | AP8: 449.95
A9: TRX0193 | B9: 45403 | C9: =TEXT(B9,"DD") -> 21 | D9: =TEXT(B9,"mm") -> 04 | E9: =TEXT(B9,"YYYY") -> 2024 | F9: CUST024 | G9: Dorothy Nelson | H9: P003 | I9: Headphones | J9: Electronics | K9: 5 | L9: 149.99 | M9: Credit Card | N9: Central | O9: Standard | P9: 44418 | Q9: 749.95 | T9: =' Dataset'!$B9-' Dataset'!$P9 -> 985 | U9: =EOMONTH(' Dataset'!$B9, 0) -> 45412 | V9: 749.95 | X9: Charles Allen | Y9: =SUMIFS(Dataset[Total_Amount], Dataset[Customer_Name], X9) -> 5089.73 | Z9: TRX0080 | AA9: 45500 | AB9: 27 | AC9: 07 | AD9: 2024 | AE9: CUST018 | AF9: Barbara Young | AG9: P009 | AH9: Monitor | AI9: Electronics | AJ9: 2 | AK9: 249.99 | AL9: Cash | AM9: North | AN9: Premium | AO9: 45164 | AP9: 499.98
A10: TRX0240 | B10: 45403 | C10: =TEXT(B10,"DD") -> 21 | D10: =TEXT(B10,"mm") -> 04 | E10: =TEXT(B10,"YYYY") -> 2024 | F10: CUST017 | G10: Charles Allen | H10: P005 | I10: Blender | J10: Appliances | K10: 3 | L10: 59.99 | M10: Debit Card | N10: South | O10: Basic | P10: 45007 | Q10: 179.97 | T10: =' Dataset'!$B10-' Dataset'!$P10 -> 396 | U10: =EOMONTH(' Dataset'!$B10, 0) -> 45412 | V10: 179.97 | X10: Robert Thomas | Y10: =SUMIFS(Dataset[Total_Amount], Dataset[Customer_Name], X10) -> 3509.9 | Z10: TRX0217 | AA10: 45503 | AB10: 30 | AC10: 07 | AD10: 2024 | AE10: CUST025 | AF10: Mark Carter | AG10: P002 | AH10: Smartphone | AI10: Electronics | AJ10: 2 | AK10: 699.99 | AL10: Credit Card | AM10: North | AN10: Premium | AO10: 44999 | AP10: 1399.98
A11: TRX0135 | B11: 45405 | C11: =TEXT(B11,"DD") -> 23 | D11: =TEXT(B11,"mm") -> 04 | E11: =TEXT(B11,"YYYY") -> 2024 | F11: CUST009 | G11: Robert Thomas | H11: P001 | I11: Laptop | J11: Electronics | K11: 3 | L11: 899.99 | M11: PayPal | N11: East | O11: Standard | P11: 45299 | Q11: 2699.97 | T11: =' Dataset'!$B11-' Dataset'!$P11 -> 106 | U11: =EOMONTH(' Dataset'!$B11, 0) -> 45412 | V11: 2699.97 | X11: Karen Hill | Y11: =SUMIFS(Dataset[Total_Amount], Dataset[Customer_Name], X11) -> 8009.77 | Z11: TRX0101 | AA11: 45513 | AB11: 09 | AC11: 08 | AD11: 2024 | AE11: CUST010 | AF11: Maria Garcia | AG11: P010 | AH11: Keyboard | AI11: Electronics | AJ11: 1 | AK11: 89.99 | AL11: Credit Card | AM11: North | AN11: Standard | AO11: 45393 | AP11: 89.99
A12: TRX0185 | B12: 45408 | C12: =TEXT(B12,"DD") -> 26 | D12: =TEXT(B12,"mm") -> 04 | E12: =TEXT(B12,"YYYY") -> 2024 | F12: CUST026 | G12: Karen Hill | H12: P005 | I12: Blender | J12: Appliances | K12: 3 | L12: 59.99 | M12: Cash | N12: West | O12: Premium | P12: 45207 | Q12: 179.97 | T12: =' Dataset'!$B12-' Dataset'!$P12 -> 201 | U12: =EOMONTH(' Dataset'!$B12, 0) -> 45412 | V12: 179.97 | X12: Susan Green | Y12: =SUMIFS(Dataset[Total_Amount], Dataset[Customer_Name], X12) -> 1979.89 | Z12: TRX0098 | AA12: 45517 | AB12: 13 | AC12: 08 | AD12: 2024 | AE12: CUST026 | AF12: Karen Hill | AG12: P009 | AH12: Monitor | AI12: Electronics | AJ12: 3 | AK12: 249.99 | AL12: PayPal | AM12: North | AN12: Premium | AO12: 44465 | AP12: 749.97
A13: TRX0138 | B13: 45408 | C13: =TEXT(B13,"DD") -> 26 | D13: =TEXT(B13,"mm") -> 04 | E13: =TEXT(B13,"YYYY") -> 2024 | F13: CUST022 | G13: Susan Green | H13: P008 | I13: Bookshelf | J13: Furniture | K13: 1 | L13: 149.99 | M13: Credit Card | N13: West | O13: Standard | P13: 45103 | Q13: 149.99 | T13: =' Dataset'!$B13-' Dataset'!$P13 -> 305 | U13: =EOMONTH(' Dataset'!$B13, 0) -> 45412 | V13: 149.99 | X13: Peter Richardson | Y13: =SUMIFS(Dataset[Total_Amount], Dataset[Customer_Name], X13) -> 5949.85 | Z13: TRX0248 | AA13: 45534 | AB13: 30 | AC13: 08 | AD13: 2024 | AE13: CUST032 | AF13: Sandra Phillips | AG13: P002 | AH13: Smartphone | AI13: Electronics | AJ13: 2 | AK13: 699.99 | AL13: Credit Card | AM13: North | AN13: Premium | AO13: 44421 | AP13: 1399.98
A14: TRX0209 | B14: 45408 | C14: =TEXT(B14,"DD") -> 26 | D14: =TEXT(B14,"mm") -> 04 | E14: =TEXT(B14,"YYYY") -> 2024 | F14: CUST046 | G14: Kathleen Bennett | H14: P008 | I14: Bookshelf | J14: Furniture | K14: 5 | L14: 149.99 | M14: Debit Card | N14: North | O14: Basic | P14: 44830 | Q14: 749.95 | T14: =' Dataset'!$B14-' Dataset'!$P14 -> 578 | U14: =EOMONTH(' Dataset'!$B14, 0) -> 45412 | V14: 749.95 | X14: Dennis Gray | Y14: =SUMIFS(Dataset[Total_Amount], Dataset[Customer_Name], X14) -> 479.92 | Z14: TRX0074 | AA14: 45537 | AB14: 02 | AC14: 09 | AD14: 2024 | AE14: CUST023 | AF14: Paul Baker | AG14: P009 | AH14: Monitor | AI14: Electronics | AJ14: 1 | AK14: 249.99 | AL14: Debit Card | AM14: North | AN14: Premium | AO14: 45332 | AP14: 249.99
A15: TRX0246 | B15: 45408 | C15: =TEXT(B15,"DD") -> 26 | D15: =TEXT(B15,"mm") -> 04 | E15: =TEXT(B15,"YYYY") -> 2024 | F15: CUST041 | G15: Peter Richardson | H15: P008 | I15: Bookshelf | J15: Furniture | K15: 3 | L15: 149.99 | M15: Cash | N15: North | O15: Premium | P15: 44806 | Q15: 449.97 | T15: =' Dataset'!$B15-' Dataset'!$P15 -> 602 | U15: =EOMONTH(' Dataset'!$B15, 0) -> 45412 | V15: 449.97 | X15: Michelle Rogers | Y15: =SUMIFS(Dataset[Total_Amount], Dataset[Customer_Name], X15) -> 4199.94 | Z15: TRX0005 | AA15: 45550 | AB15: 15 | AC15: 09 | AD15: 2024 | AE15: CUST042 | AF15: Ruth Brooks | AG15: P003 | AH15: Headphones | AI15: Electronics | AJ15: 4 | AK15: 149.99 | AL15: Cash | AM15: North | AN15: Basic | AO15: 44909 | AP15: 599.96
... A37: TRX0232 | B37: 45434 | C37: =TEXT(B37,"DD") -> 22 | D37: =TEXT(B37,"mm") -> 05 | E37: =TEXT(B37,"YYYY") -> 2024 | F37: CUST012 | G37: Patricia Moore | H37: P007 | I37: Desk | J37: Furniture | K37: 3 | L37: 299.99 | M37: Credit Card | N37: East | O37: Basic | P37: 44824 | Q37: 899.97 | T37: =' Dataset'!$B37-' Dataset'!$P37 -> 610 | U37: =EOMONTH(' Dataset'!$B37, 0) -> 45443 | V37: 899.97 | X37: Raymond Ross | Y37: =SUMIFS(Dataset[Total_Amount], Dataset[Customer_Name], X37) -> 3669.85 | Z37: TRX0064 | AA37: 45758 | AB37: 11 | AC37: 04 | AD37: 2025 | AE37: CUST031 | AF37: Steven Turner | AG37: P010 | AH37: Keyboard | AI37: Electronics | AJ37: 3 | AK37: 89.99 | AL37: Debit Card | AM37: North | AN37: Premium | AO37: 44878 | AP37: 269.97
A38: TRX0021 | B38: 45435 | C38: =TEXT(B38,"DD") -> 23 | D38: =TEXT(B38,"mm") -> 05 | E38: =TEXT(B38,"YYYY") -> 2024 | F38: CUST006 | G38: Lisa Anderson | H38: P004 | I38: Coffee Maker | J38: Appliances | K38: 3 | L38: 79.99 | M38: Cash | N38: South | O38: Basic | P38: 45046 | Q38: 239.97 | T38: =' Dataset'!$B38-' Dataset'!$P38 -> 389 | U38: =EOMONTH(' Dataset'!$B38, 0) -> 45443 | V38: 239.97 | X38: David Martinez | Y38: =SUMIFS(Dataset[Total_Amount], Dataset[Customer_Name], X38) -> 1809.84
A39: TRX0245 | B39: 45438 | C39: =TEXT(B39,"DD") -> 26 | D39: =TEXT(B39,"mm") -> 05 | E39: =TEXT(B39,"YYYY") -> 2024 | F39: CUST031 | G39: Steven Turner | H39: P006 | I39: Office Chair | J39: Furniture | K39: 3 | L39: 199.99 | M39: Credit Card | N39: North | O39: Premium | P39: 45292 | Q39: 599.97 | T39: =' Dataset'!$B39-' Dataset'!$P39 -> 146 | U39: =EOMONTH(' Dataset'!$B39, 0) -> 45443 | V39: 599.97 | X39: Margaret Wright | Y39: =SUMIFS(Dataset[Total_Amount], Dataset[Customer_Name], X39) -> 2099.88
A40: TRX0015 | B40: 45440 | C40: =TEXT(B40,"DD") -> 28 | D40: =TEXT(B40,"mm") -> 05 | E40: =TEXT(B40,"YYYY") -> 2024 | F40: CUST008 | G40: Jennifer Taylor | H40: P002 | I40: Smartphone | J40: Electronics | K40: 5 | L40: 699.99 | M40: PayPal | N40: West | O40: Standard | P40: 44407 | Q40: 3499.95 | T40: =' Dataset'!$B40-' Dataset'!$P40 -> 1033 | U40: =EOMONTH(' Dataset'!$B40, 0) -> 45443 | V40: 3499.95 | X40: Frank Torres | Y40: =SUMIFS(Dataset[Total_Amount], Dataset[Customer_Name], X40) -> 1479.91
A41: TRX0202 | B41: 45441 | C41: =TEXT(B41,"DD") -> 29 | D41: =TEXT(B41,"mm") -> 05 | E41: =TEXT(B41,"YYYY") -> 2024 | F41: CUST035 | G41: Harry Morgan | H41: P010 | I41: Keyboard | J41: Electronics | K41: 3 | L41: 89.99 | M41: PayPal | N41: Central | O41: Premium | P41: 45120 | Q41: 269.97 | T41: =' Dataset'!$B41-' Dataset'!$P41 -> 321 | U41: =EOMONTH(' Dataset'!$B41, 0) -> 45443 | V41: 269.97 | X41: Gerald Murphy | Y41: =SUMIFS(Dataset[Total_Amount], Dataset[Customer_Name], X41) -> 6379.87
A42: TRX0042 | B42: 45443 | C42: =TEXT(B42,"DD") -> 31 | D42: =TEXT(B42,"mm") -> 05 | E42: =TEXT(B42,"YYYY") -> 2024 | F42: CUST019 | G42: Daniel King | H42: P004 | I42: Coffee Maker | J42: Appliances | K42: 1 | L42: 79.99 | M42: Cash | N42: North | O42: Standard | P42: 44917 | Q42: 79.99 | T42: =' Dataset'!$B42-' Dataset'!$P42 -> 526 | U42: =EOMONTH(' Dataset'!$B42, 0) -> 45443 | V42: 79.99 | X42: Elizabeth Hall | Y42: =SUMIFS(Dataset[Total_Amount], Dataset[Customer_Name], X42) -> 3649.86
A43: TRX0128 | B43: 45444 | C43: =TEXT(B43,"DD") -> 01 | D43: =TEXT(B43,"mm") -> 06 | E43: =TEXT(B43,"YYYY") -> 2024 | F43: CUST040 | G43: Sharon Butler | H43: P005 | I43: Blender | J43: Appliances | K43: 2 | L43: 59.99 | M43: Cash | N43: West | O43: Basic | P43: 45390 | Q43: 119.98 | T43: =' Dataset'!$B43-' Dataset'!$P43 -> 54 | U43: =EOMONTH(' Dataset'!$B43, 0) -> 45473 | V43: 119.98 | X43: Lawrence Reed | Y43: =SUMIFS(Dataset[Total_Amount], Dataset[Customer_Name], X43) -> 6989.77
A44: TRX0117 | B44: 45444 | C44: =TEXT(B44,"DD") -> 01 | D44: =TEXT(B44,"mm") -> 06 | E44: =TEXT(B44,"YYYY") -> 2024 | F44: CUST017 | G44: Charles Allen | H44: P010 | I44: Keyboard | J44: Electronics | K44: 1 | L44: 89.99 | M44: Cash | N44: North | O44: Basic | P44: 45141 | Q44: 89.99 | T44: =' Dataset'!$B44-' Dataset'!$P44 -> 303 | U44: =EOMONTH(' Dataset'!$B44, 0) -> 45473 | V44: 89.99 | X44: Carol Evans | Y44: =SUMIFS(Dataset[Total_Amount], Dataset[Customer_Name], X44) -> 1149.93
A45: TRX0208 | B45: 45446 | C45: =TEXT(B45,"DD") -> 03 | D45: =TEXT(B45,"mm") -> 06 | E45: =TEXT(B45,"YYYY") -> 2024 | F45: CUST004 | G45: Sarah Davis | H45: P010 | I45: Keyboard | J45: Electronics | K45: 5 | L45: 89.99 | M45: Credit Card | N45: East | O45: Standard | P45: 44587 | Q45: 449.95 | T45: =' Dataset'!$B45-' Dataset'!$P45 -> 859 | U45: =EOMONTH(' Dataset'!$B45, 0) -> 45473 | V45: 449.95 | X45: Sandra Phillips | Y45: =SUMIFS(Dataset[Total_Amount], Dataset[Customer_Name], X45) -> 6349.83
A46: TRX0234 | B46: 45449 | C46: =TEXT(B46,"DD") -> 06 | D46: =TEXT(B46,"mm") -> 06 | E46: =TEXT(B46,"YYYY") -> 2024 | F46: CUST013 | G46: Joseph Jackson | H46: P009 | I46: Monitor | J46: Electronics | K46: 5 | L46: 249.99 | M46: Credit Card | N46: East | O46: Standard | P46: 44707 | Q46: 1249.95 | T46: =' Dataset'!$B46-' Dataset'!$P46 -> 742 | U46: =EOMONTH(' Dataset'!$B46, 0) -> 45473 | V46: 1249.95 | X46: Ruth Brooks | Y46: =SUMIFS(Dataset[Total_Amount], Dataset[Customer_Name], X46) -> 1749.92
A47: TRX0121 | B47: 45449 | C47: =TEXT(B47,"DD") -> 06 | D47: =TEXT(B47,"mm") -> 06 | E47: =TEXT(B47,"YYYY") -> 2024 | F47: CUST028 | G47: Betty Campbell | H47: P010 | I47: Keyboard | J47: Electronics | K47: 1 | L47: 89.99 | M47: Credit Card | N47: South | O47: Standard | P47: 44582 | Q47: 89.99 | T47: =' Dataset'!$B47-' Dataset'!$P47 -> 867 | U47: =EOMONTH(' Dataset'!$B47, 0) -> 45473 | V47: 89.99 | X47: William White | Y47: =SUMIFS(Dataset[Total_Amount], Dataset[Customer_Name], X47) -> 4749.91
A48: TRX0220 | B48: 45450 | C48: =TEXT(B48,"DD") -> 07 | D48: =TEXT(B48,"mm") -> 06 | E48: =TEXT(B48,"YYYY") -> 2024 | F48: CUST003 | G48: Michael Brown | H48: P008 | I48: Bookshelf | J48: Furniture | K48: 2 | L48: 149.99 | M48: Cash | N48: East | O48: Premium | P48: 44645 | Q48: 299.98 | T48: =' Dataset'!$B48-' Dataset'!$P48 -> 805 | U48: =EOMONTH(' Dataset'!$B48, 0) -> 45473 | V48: 299.98 | X48: Richard Lee | Y48: =SUMIFS(Dataset[Total_Amount], Dataset[Customer_Name], X48) -> 739.93
A49: TRX0093 | B49: 45452 | C49: =TEXT(B49,"DD") -> 09 | D49: =TEXT(B49,"mm") -> 06 | E49: =TEXT(B49,"YYYY") -> 2024 | F49: CUST050 | G49: Julie Foster | H49: P005 | I49: Blender | J49: Appliances | K49: 4 | L49: 59.99 | M49: Cash | N49: East | O49: Standard | P49: 44435 | Q49: 239.96 | T49: =' Dataset'!$B49-' Dataset'!$P49 -> 1017 | U49: =EOMONTH(' Dataset'!$B49, 0) -> 45473 | V49: 239.96 | X49: Douglas Watson | Y49: =SUMIFS(Dataset[Total_Amount], Dataset[Customer_Name], X49) -> 4829.89
... A52: TRX0154 | B52: 45459 | C52: =TEXT(B52,"DD") -> 16 | D52: =TEXT(B52,"mm") -> 06 | E52: =TEXT(B52,"YYYY") -> 2024 | F52: CUST023 | G52: Paul Baker | H52: P001 | I52: Laptop | J52: Electronics | K52: 5 | L52: 899.99 | M52: Credit Card | N52: South | O52: Standard | P52: 44974 | Q52: 4499.95 | T52: =' Dataset'!$B52-' Dataset'!$P52 -> 485 | U52: =EOMONTH(' Dataset'!$B52, 0) -> 45473 | V52: 4499.95 | X52: John Smith | Y52: =SUMIFS(Dataset[Total_Amount], Dataset[Customer_Name], X52) -> 599.96
A53: TRX0044 | B53: 45459 | C53: =TEXT(B53,"DD") -> 16 | D53: =TEXT(B53,"mm") -> 06 | E53: =TEXT(B53,"YYYY") -> 2024 | F53: CUST029 | G53: Edward Mitchell | H53: P001 | I53: Laptop | J53: Electronics | K53: 5 | L53: 899.99 | M53: PayPal | N53: East | O53: Premium | P53: 45278 | Q53: 4499.95 | T53: =' Dataset'!$B53-' Dataset'!$P53 -> 181 | U53: =EOMONTH(' Dataset'!$B53, 0) -> 45473 | V53: 4499.95
A54: TRX0061 | B54: 45460 | C54: =TEXT(B54,"DD") -> 17 | D54: =TEXT(B54,"mm") -> 06 | E54: =TEXT(B54,"YYYY") -> 2024 | F54: CUST028 | G54: Betty Campbell | H54: P005 | I54: Blender | J54: Appliances | K54: 1 | L54: 59.99 | M54: Debit Card | N54: West | O54: Premium | P54: 45190 | Q54: 59.99 | T54: =' Dataset'!$B54-' Dataset'!$P54 -> 270 | U54: =EOMONTH(' Dataset'!$B54, 0) -> 45473 | V54: 59.99
A55: TRX0150 | B55: 45460 | C55: =TEXT(B55,"DD") -> 17 | D55: =TEXT(B55,"mm") -> 06 | E55: =TEXT(B55,"YYYY") -> 2024 | F55: CUST008 | G55: Jennifer Taylor | H55: P007 | I55: Desk | J55: Furniture | K55: 2 | L55: 299.99 | M55: Debit Card | N55: East | O55: Standard | P55: 45253 | Q55: 599.98 | T55: =' Dataset'!$B55-' Dataset'!$P55 -> 207 | U55: =EOMONTH(' Dataset'!$B55, 0) -> 45473 | V55: 599.98
A56: TRX0025 | B56: 45468 | C56: =TEXT(B56,"DD") -> 25 | D56: =TEXT(B56,"mm") -> 06 | E56: =TEXT(B56,"YYYY") -> 2024 | F56: CUST049 | G56: Raymond Ross | H56: P010 | I56: Keyboard | J56: Electronics | K56: 4 | L56: 89.99 | M56: Debit Card | N56: South | O56: Basic | P56: 45281 | Q56: 359.96 | T56: =' Dataset'!$B56-' Dataset'!$P56 -> 187 | U56: =EOMONTH(' Dataset'!$B56, 0) -> 45473 | V56: 359.96
A57: TRX0078 | B57: 45469 | C57: =TEXT(B57,"DD") -> 26 | D57: =TEXT(B57,"mm") -> 06 | E57: =TEXT(B57,"YYYY") -> 2024 | F57: CUST021 | G57: Kevin Scott | H57: P004 | I57: Coffee Maker | J57: Appliances | K57: 1 | L57: 79.99 | M57: PayPal | N57: Central | O57: Premium | P57: 45352 | Q57: 79.99 | T57: =' Dataset'!$B57-' Dataset'!$P57 -> 117 | U57: =EOMONTH(' Dataset'!$B57, 0) -> 45473 | V57: 79.99
A58: TRX0007 | B58: 45469 | C58: =TEXT(B58,"DD") -> 26 | D58: =TEXT(B58,"mm") -> 06 | E58: =TEXT(B58,"YYYY") -> 2024 | F58: CUST009 | G58: Robert Thomas | H58: P010 | I58: Keyboard | J58: Electronics | K58: 2 | L58: 89.99 | M58: Cash | N58: West | O58: Basic | P58: 44438 | Q58: 179.98 | T58: =' Dataset'!$B58-' Dataset'!$P58 -> 1031 | U58: =EOMONTH(' Dataset'!$B58, 0) -> 45473 | V58: 179.98
A59: TRX0184 | B59: 45471 | C59: =TEXT(B59,"DD") -> 28 | D59: =TEXT(B59,"mm") -> 06 | E59: =TEXT(B59,"YYYY") -> 2024 | F59: CUST046 | G59: Kathleen Bennett | H59: P002 | I59: Smartphone | J59: Electronics | K59: 3 | L59: 699.99 | M59: Credit Card | N59: East | O59: Premium | P59: 45102 | Q59: 2099.97 | T59: =' Dataset'!$B59-' Dataset'!$P59 -> 369 | U59: =EOMONTH(' Dataset'!$B59, 0) -> 45473 | V59: 2099.97
A60: TRX0104 | B60: 45471 | C60: =TEXT(B60,"DD") -> 28 | D60: =TEXT(B60,"mm") -> 06 | E60: =TEXT(B60,"YYYY") -> 2024 | F60: CUST012 | G60: Patricia Moore | H60: P001 | I60: Laptop | J60: Electronics | K60: 4 | L60: 899.99 | M60: Credit Card | N60: East | O60: Premium | P60: 44993 | Q60: 3599.96 | T60: =' Dataset'!$B60-' Dataset'!$P60 -> 478 | U60: =EOMONTH(' Dataset'!$B60, 0) -> 45473 | V60: 3599.96
A61: TRX0127 | B61: 45472 | C61: =TEXT(B61,"DD") -> 29 | D61: =TEXT(B61,"mm") -> 06 | E61: =TEXT(B61,"YYYY") -> 2024 | F61: CUST030 | G61: Helen Roberts | H61: P008 | I61: Bookshelf | J61: Furniture | K61: 1 | L61: 149.99 | M61: PayPal | N61: East | O61: Basic | P61: 44851 | Q61: 149.99 | T61: =' Dataset'!$B61-' Dataset'!$P61 -> 621 | U61: =EOMONTH(' Dataset'!$B61, 0) -> 45473 | V61: 149.99
A62: TRX0096 | B62: 45474 | C62: =TEXT(B62,"DD") -> 01 | D62: =TEXT(B62,"mm") -> 07 | E62: =TEXT(B62,"YYYY") -> 2024 | F62: CUST002 | G62: Emma Wilson | H62: P010 | I62: Keyboard | J62: Electronics | K62: 2 | L62: 89.99 | M62: PayPal | N62: Central | O62: Premium | P62: 45275 | Q62: 179.98 | T62: =' Dataset'!$B62-' Dataset'!$P62 -> 199 | U62: =EOMONTH(' Dataset'!$B62, 0) -> 45504 | V62: 179.98
A63: TRX0192 | B63: 45475 | C63: =TEXT(B63,"DD") -> 02 | D63: =TEXT(B63,"mm") -> 07 | E63: =TEXT(B63,"YYYY") -> 2024 | F63: CUST017 | G63: Charles Allen | H63: P010 | I63: Keyboard | J63: Electronics | K63: 1 | L63: 89.99 | M63: PayPal | N63: West | O63: Standard | P63: 44802 | Q63: 89.99 | T63: =' Dataset'!$B63-' Dataset'!$P63 -> 673 | U63: =EOMONTH(' Dataset'!$B63, 0) -> 45504 | V63: 89.99
...

Sheet Pivot & Charts
A2: Month | B2: Sum of Total_Amount
A3: 01 | B3: 25799.15 | D3: Category | E3: Sum of Total_Amount | G3: Customer_Name | H3: Sum of Total_Amount | J3: Payment_Method | K3: Count of Transaction_ID
A4: 02 | B4: 16069.38 | D4: Appliances | E4: 8338.74 | G4: Barbara Young | H4: 10649.8 | J4: Cash | K4: 76
A5: 03 | B5: 19899.38 | D5: Electronics | E5: 171756.05 | G5: Daniel King | H5: 7309.8 | J5: Credit Card | K5: 68
A6: 04 | B6: 27899.16 | D6: Furniture | E6: 49097.68 | G6: Dorothy Nelson | H6: 8269.79 | J6: Debit Card | K6: 54
A7: 05 | B7: 17039.35 | D7: Grand Total | E7: 229192.47 | G7: Edward Mitchell | H7: 11919.77 | J7: PayPal | K7: 52
A8: 06 | B8: 19299.45 | G8: Joseph Jackson | H8: 6949.84 | J8: Grand Total | K8: 250
A9: 07 | B9: 18479.4 | G9: Karen Hill | H9: 8009.77
A10: 08 | B10: 15759.43 | G10: Lawrence Reed | H10: 6989.77
A11: 09 | B11: 12989.51 | G11: Mark Carter | H11: 15659.65
A12: 10 | B12: 20609.52 | G12: Patricia Moore | H12: 9799.73
A13: 11 | B13: 12309.44 | G13: Paul Baker | H13: 8309.74
A14: 12 | B14: 23039.3 | G14: Grand Total | H14: 93867.66
A15: Grand Total | B15: 229192.47

Sheet Linear_Regression
A1: SUMMARY OUTPUT
A3: Regression Statistics
A4: Multiple R | B4: 0.45809869
A5: R Square | B5: 0.20985441
A6: Adjusted R Square | B6: 0.20665544
A7: Standard Error | B7: 921.40854
A8: Observations | B8: 249
A10: ANOVA
B11: df | C11: SS | D11: MS | E11: F | F11: Significance F
A12: Regression | B12: 1 | C12: 55694513 | D12: 55694513 | E12: 65.60062 | F12: 2.5391277e-14
A13: Residual | B13: 247 | C13: 2.0970144e+08 | D13: 848993.7
A14: Total | B14: 248 | C14: 2.6539596e+08
B16: Coefficients | C16: Standard Error | D16: t Stat | E16: P-value | F16: Lower 95% | G16: Upper 95% | H16: Lower 95.0% | I16: Upper 95.0%
A17: Intercept | B17: -148.18856 | C17: 143.94399 | D17: -1.0294877 | E17: 0.30425761 | F17: -431.70277 | G17: 135.32564 | H17: -431.70277 | I17: 135.32564
A18: 3 | B18: 353.7886 | C18: 43.680728 | D18: 8.0994209 | E18: 2.5391277e-14 | F18: 267.7544 | G18: 439.82281 | H18: 267.7544 | I18: 439.82281

Sheet Scenario Summary
B2: Scenario Summary
D3: Current Values: | E3: Low Sales | F3: Medium Sales | G3: High Sales
E4: Created by CHARMY R PATEL on 20-01-2026 | F4: Created by CHARMY R PATEL on 20-01-2026 | G4: Created by CHARMY R PATEL on 20-01-2026
B5: Changing Cells:
C6: $C$2 | D6: 200 | E6: 100 | F6: 150 | G6: 200
C7: $C$3 | D7: 20 | E7: 5 | F7: 10 | G7: 20
B8: Result Cells:
C9: $C$4 | D9: 4000 | E9: 500 | F9: 1500 | G9: 4000
B10: Notes: Current Values column represents values of changing cells at
B11: time Scenario Summary Report was created. Changing cells for each
B12: scenario are highlighted in gray.

Sheet what if analysis
B1: Scenario Manager | E1: Goal Seek
B2: Unit Price | C2: 200 | E2: Unit Price | F2: 1000
B3: Quantity | C3: 20 | E3: Quantity | F3: 3
B4: Total Amount | C4: =C2*C3 -> 4000 | E4: Total Amount | F4: =F2*F3 -> 3000
